Defaulting to user installation because normal site-packages is not writeable
Collecting disnake[discord]
  Cloning https://github.com/EQUENOS/disnake to /tmp/pip-install-xxwmet5f/disnake_44c5a64741954fbdafa5e39ebf5f87d0
  Running command git clone -q https://github.com/EQUENOS/disnake /tmp/pip-install-xxwmet5f/disnake_44c5a64741954fbdafa5e39ebf5f87d0
  Resolved https://github.com/EQUENOS/disnake to commit 4d0b6d1a939c70c0128b5db75c85fcd439aa596d
ERROR: File "setup.py" not found for legacy project disnake[discord] from git+https://github.com/EQUENOS/disnake#egg=disnake[discord].
WARNING: You are using pip version 21.2.4; however, version 21.3.1 is available.
You should consider upgrading via the '/usr/bin/python3.7 -m pip install --upgrade pip' command.
Defaulting to user installation because normal site-packages is not writeable
Requirement already satisfied: disnake==2.3.0 in ./.local/lib/python3.9/site-packages (2.3.0)
Requirement already satisfied: aiohttp<3.9.0,>=3.7.0 in ./.local/lib/python3.9/site-packages (from disnake==2.3.0) (3.8.1)
Requirement already satisfied: multidict<7.0,>=4.5 in ./.local/lib/python3.9/site-packages (from aiohttp<3.9.0,>=3.7.0->disnake==2.3.0) (5.2.0)
Requirement already satisfied: frozenlist>=1.1.1 in ./.local/lib/python3.9/site-packages (from aiohttp<3.9.0,>=3.7.0->disnake==2.3.0) (1.2.0)
Requirement already satisfied: yarl<2.0,>=1.0 in ./.local/lib/python3.9/site-packages (from aiohttp<3.9.0,>=3.7.0->disnake==2.3.0) (1.7.2)
Requirement already satisfied: async-timeout<5.0,>=4.0.0a3 in ./.local/lib/python3.9/site-packages (from aiohttp<3.9.0,>=3.7.0->disnake==2.3.0) (4.0.2)
Requirement already satisfied: attrs>=17.3.0 in ./.local/lib/python3.9/site-packages (from aiohttp<3.9.0,>=3.7.0->disnake==2.3.0) (21.4.0)
Requirement already satisfied: charset-normalizer<3.0,>=2.0 in ./.local/lib/python3.9/site-packages (from aiohttp<3.9.0,>=3.7.0->disnake==2.3.0) (2.0.10)
Requirement already satisfied: aiosignal>=1.1.2 in ./.local/lib/python3.9/site-packages (from aiohttp<3.9.0,>=3.7.0->disnake==2.3.0) (1.2.0)
Requirement already satisfied: idna>=2.0 in /usr/lib/python3/dist-packages (from yarl<2.0,>=1.0->aiohttp<3.9.0,>=3.7.0->disnake==2.3.0) (2.6)
WARNING: You are using pip version 21.2.4; however, version 21.3.1 is available.
You should consider upgrading via the '/usr/bin/python3.7 -m pip install --upgrade pip' command.
Defaulting to user installation because normal site-packages is not writeable
Requirement already satisfied: python-dotenv==0.18.0 in ./.local/lib/python3.9/site-packages (0.18.0)
WARNING: You are using pip version 21.2.4; however, version 21.3.1 is available.
You should consider upgrading via the '/usr/bin/python3.7 -m pip install --upgrade pip' command.
Defaulting to user installation because normal site-packages is not writeable
Requirement already satisfied: aiosqlite==0.17.0 in ./.local/lib/python3.9/site-packages (0.17.0)
Requirement already satisfied: typing_extensions>=3.7.2 in ./.local/lib/python3.9/site-packages (from aiosqlite==0.17.0) (4.0.1)
WARNING: You are using pip version 21.2.4; however, version 21.3.1 is available.
You should consider upgrading via the '/usr/bin/python3.7 -m pip install --upgrade pip' command.
[Leaderboard] Loaded
[CharCount] Loaded
[General] Loaded
Main DataBase Connected
Traceback (most recent call last):
  File "/home/minecraft/multicraft/servers/server251005/.local/lib/python3.9/site-packages/disnake/client.py", line 680, in connect
    self.ws = await asyncio.wait_for(coro, timeout=60.0)
  File "/usr/lib/python3.9/asyncio/tasks.py", line 481, in wait_for
    return fut.result()
  File "/home/minecraft/multicraft/servers/server251005/.local/lib/python3.9/site-packages/disnake/gateway.py", line 330, in from_client
    socket = await client.http.ws_connect(gateway)
  File "/home/minecraft/multicraft/servers/server251005/.local/lib/python3.9/site-packages/disnake/http.py", line 245, in ws_connect
    return await self.__session.ws_connect(url, **kwargs)
  File "/home/minecraft/multicraft/servers/server251005/.local/lib/python3.9/site-packages/aiohttp/client.py", line 792, in _ws_connect
    raise WSServerHandshakeError(
aiohttp.client_exceptions.WSServerHandshakeError: 409, message='Invalid response status', url=URL('wss://gateway.discord.gg/?encoding=json&v=9&compress=zlib-stream')

During handling of the above exception, another exception occurred:

Traceback (most recent call last):
  File "/home/minecraft/multicraft/servers/server251005/bot.py", line 105, in <module>
    bot.run(TOKEN)
  File "/home/minecraft/multicraft/servers/server251005/.local/lib/python3.9/site-packages/disnake/client.py", line 843, in run
    return future.result()
  File "/home/minecraft/multicraft/servers/server251005/.local/lib/python3.9/site-packages/disnake/client.py", line 822, in runner
    await self.start(*args, **kwargs)
  File "/home/minecraft/multicraft/servers/server251005/.local/lib/python3.9/site-packages/disnake/client.py", line 786, in start
    await self.connect(reconnect=reconnect)
  File "/home/minecraft/multicraft/servers/server251005/.local/lib/python3.9/site-packages/disnake/client.py", line 738, in connect
    ws_params.update(sequence=self.ws.sequence, resume=True, session=self.ws.session_id)
AttributeError: 'NoneType' object has no attribute 'sequence'
